Workbook

Sheet 리뷰 655건
A1: 번호 | B1: 작성일 | C1: 별점 | D1: 도움돼요 | E1: 성격 | F1: 주제 | G1: 본문
A2: 0 | B2: 2026-09-17 | C2: 1 | D2: 0 | E2: 고장 | F2: 앱 튕김·먹통·프리징 | G2: 최신소스가 아니라는데요.
A3: 1 | B3: 2026-09-17 | C3: 1 | D3: 0 | E3: 설계 | F3: 촬영 시각·위치가 자동으로 안 붙음 | G3: 신고 접수하였는데 제보 사진 촬영후 업로드하면 자동으로 일시가 등록되어 이첩되는것으로 알았지만 실제 행정처리 기관에서는 사진상에 일시가 이첩되지 않아서 처리되지 않는 사례가 발생함 이러한 부분을 개선처리 하였으면 합니다.
A4: 2 | B4: 2026-09-17 | C4: 1 | D4: 1 | E4: 고장 | F4: 앱 튕김·먹통·프리징 | G4: 매번 최신소스를 쳐 받으라며 앱 기능 이용이 안되는데 이딴 어플을 국민들 쓰라고 계속 방치하는게 맞습니까? 세금 엄한곳에 낭비하지말고 정당한 기술비 드리고 실력있는 전문 개발자 초빙하여 제대로 만드세요 일 좀 제대로 하세요
A5: 3 | B5: 2026-09-17 | C5: 1 | D5: 0 | E5: 행정처리 | F5: 불수용·반려에 대한 불신 | G5: 열심히 신고하면 뭐함 담당 공무원들이 불수용하는데 ㅋㅋㅋ 뭘 그렇게 봐줌
A6: 4 | B6: 2026-09-17 | C6: 1 | D6: 0 | G6: 신고해서 처리된적이 없음. 문자로 신고하는게 나을듯
A7: 5 | B7: 2026-09-16 | C7: 1 | D7: 0 | E7: 고장 | F7: 앱 튕김·먹통·프리징, 제출·다음 단계 진행 불가 | G7: 3.2.6 업데이트 하고 업로드 진행현황 팝업 스타일 바뀐뒤로 내용 다 입력하고 제출 눌러도 반응을 안합니다 제출을 누르면 그 순간 핸드폰 GPS 리딩만 잠깐 하고 그대로 먹통이에요.
A8: 6 | B8: 2026-09-16 | C8: 1 | D8: 0 | E8: 고장 | F8: 앱 튕김·먹통·프리징 | G8: 온갖 오류가 너무 많고, 오류 팝업이 뜨는 타이밍이 항상 정보 다 입력하고나서 떠서 개빡칩니다. 최신 소스 아니라고 다시 키라는데 몇번을 다시 켜도 똑같은 알림만 뜨고, 무슨 민원인 똥개훈련 시킵니까? 앱을 만드는 기초가 안돼있어
A9: 7 | B9: 2026-09-16 | C9: 1 | D9: 0 | E9: 고장 | F9: 로그인·인증·가입 실패 | G9: 왜 비번 제한에 대문자랑 8자가아닌 9자부터 가능하게 주접떨었는지 모르겠음 다른 사이트들이랑 비번 호환하기가 힘들어서 맨날 까먹어짐 카톡으로는 인증번호 쳐오지도 않아서 문자로만 받아야하고
A10: 8 | B10: 2026-09-16 | C10: 1 | D10: 0 | E10: 고장 | F10: 느림·로딩·버퍼링 | G10: 업로드 하는 시간좀 어찌 봐주세요 와이파이를 켜도 꺼도 시간이 너무 오래걸려요
A11: 9 | B11: 2026-09-15 | C11: 1 | D11: 0 | G11: 수고하십니다 안전신문고 내 나의신고현황이 뜨질않습니다 일부러 막은것인지, 단순 앱오류인지 확인부탁드립니다 현재 안전신문고 앱 관리 역시 적정TO로 인원이 분배되어있을텐데.. 방치만하고있다면 그 역시 소극적행정처리 및 직무유기아니겠습니까?
A12: 10 | B12: 2026-09-15 | C12: 1 | D12: 0 | G12: 업데이트가 안됨
A13: 11 | B13: 2026-09-15 | C13: 1 | D13: 0 | E13: 고장 | F13: 앱 튕김·먹통·프리징 | G13: 개가튼 최신소스
A14: 12 | B14: 2026-09-15 | C14: 1 | D14: 0 | G14: 번잡한 팝업창만 늘리고 수틀리면 신고버튼 눌리지도 않는 쓰레기를 앱이라고 만들어 놓은 담당자는 본인 마빡에 월급도둑이라고 크게 써놓고 다니길 바람
A15: 13 | B15: 2026-09-15 | C15: 1 | D15: 0 | E15: 고장 | F15: 제출·다음 단계 진행 불가 | G15: 사진첨부후 다음화면으로 안넘어감 속뒤집어짐 교차로 모퉁이주정차로 시야확보안되서 불편해 매번 발견하다 신고하는데 첨부후 예 누르면 반응없음 개선좀
A16: 14 | B16: 2026-09-15 | C16: 1 | D16: 0 | E16: 고장 | F16: 앱 튕김·먹통·프리징 | G16: 사진 찍고 업로드 하려고 하면 안 됨ㅋㅋ 초기 화면으로 돌아감 안 고쳐지냐
A17: 15 | B17: 2026-09-14 | C17: 2 | D17: 1 | G17: 각종신고를 하며 느낀건 법을 어기며 살아도 되는구나를 느낌
A18: 16 | B18: 2026-09-14 | C18: 2 | D18: 0 | E18: 행정처리 | F18: 처리 지연·결과 안내 없음 | G18: 내 신고 결과 내용을 볼수가없음
A19: 17 | B19: 2026-09-13 | C19: 1 | D19: 1 | E19: 고장 | F19: 제출·다음 단계 진행 불가 | G19: 신고 제출이 안됨
A20: 18 | B20: 2026-09-13 | C20: 1 | D20: 0 | E20: 고장 | F20: 제출·다음 단계 진행 불가 | G20: 앱 관리좀 하세요 진짜 제출 이런 기초 코딩도 못돌리면 왜 월급 받는거임? 아니 돈 받고 일하는건지도 의문임 진짜 초딩이 만든 코로나 확인앱이 이거보다 더 잘돌아감
A21: 19 | B21: 2026-09-12 | C21: 1 | D21: 1 | E21: 고장 | F21: 앱 튕김·먹통·프리징 | G21: 안전신문고 앱 계속 무반응 심각하네요 이딴 앱을 만들었나요? 아무리 다시해봐도 무반응입니다.
A22: 20 | B22: 2026-09-12 | C22: 1 | D22: 0 | E22: 고장 | F22: 제출·다음 단계 진행 불가 | G22: 최적화 쓰레기앱. 불법주차 신고하려해도 다시 확인하라고만 하고 제출 버튼 활성화가 안됨. 시민의 불편을 해소하려는 의지가 단 1도 없음.
A23: 21 | B23: 2026-09-12 | C23: 1 | D23: 1 | E23: 설계/고장 | F23: 갤러리 사진 첨부 불가(앱 카메라 강제), 제출·다음 단계 진행 불가 | G23: 신고도 안되는데 이게 왜 안전신문고 신고어플임???? 다른사람들 리뷰에 댓글달아놓은거대로 앱 내장카메라 사용했고 제출하기했는데 그 다음 화면으로 안넘어가짐 안전신문고 내 갤러리저장 된 사진으로 신고하려니 사진이 업로두가 안됨 이게 국가 세금으로 이뤄지는 어플이 맞나요??
A24: 22 | B24: 2026-09-12 | C24: 1 | D24: 1 | E24: 고장 | F24: 제출·다음 단계 진행 불가 | G24: 신고가 안됨
A25: 23 | B25: 2026-09-12 | C25: 1 | D25: 1 | E25: 고장 | F25: 제출·다음 단계 진행 불가 | G25: 아니 신고하려고하면 제출버튼 활성화가안되는데 어찌신고하란말인가?
A26: 24 | B26: 2026-09-12 | C26: 2 | D26: 0 | E26: 설계 | F26: 갤러리 사진 첨부 불가(앱 카메라 강제), 사진 화질 저하로 번호판 식별 불가, 1분 대기·현장 체류 | G26: 1. 앱내장 카메라 성능이 안좋아서 비활성화 후 핸드폰 카메라로 찍으면 그 화질을 유지 못하고 갤러리에서 해상도 저하 문제 생김. (촬영시엔 번호판이 확보되었는데, 막상 저장되면 식별 불가)번호판이라도 해상도 유지해주십쇼. 2. 불법 주정차 사진 업데이트 시, 필수를 제외한 사진(2장)은 시차 1분에 포함이 안되도록 검토 요청->주정차 처리과에서 주변 전경이 확보된 사진을 요구합니다. 총 3장을 첨부하게 된다면 2분의 시차 간격이나 필요한 애로 사항이 있음
A27: 25 | B27: 2026-09-11 | C27: 1 | D27: 1 | E27: 고장 | F27: 제출·다음 단계 진행 불가 | G27: 별한개도 아까워요 이거 제출 이후 알림 페이지 신고하시겠습니까 나오고 예를 눌러도 안넘어감 이걸 신고도 안되게 말들꺼 왜 만든건지?
A28: 26 | B28: 2026-09-11 | C28: 1 | D28: 0 | E28: 설계/고장 | F28: 작성 중 내용 유실·임시저장 없음, 사진 촬영·저장 실패, 앱 튕김·먹통·프리징 | G28: 아니 사진 찍은거 날아가기 일쑤여서 그 덕분에 불법주정차 해놓은 차들이 그 사이에 도망가기 일쑤, 사진 저장 안되고 앱튕기는것 좀 해결해주세요
A29: 27 | B29: 2026-09-11 | C29: 1 | D29: 0 | E29: 고장 | F29: 제출·다음 단계 진행 불가 | G29: 내가 리뷰는 안쓰는데 처음으로 씀 안전신문고라고 신고하라고 만든 어플이 신고가 안되면 왜 있는거임?? 이것도 분명 나라 세금으로 만들어서 운영할텐데 이딴 어플을 얼마주고 만들었는지 참으로 궁금해짐
A30: 28 | B30: 2026-09-11 | C30: 1 | D30: 0 | G30: 신고도 제대로 안되는 오류투성이 구시대UI어플
A31: 29 | B31: 2026-09-10 | C31: 5 | D31: 0 | E31: 설계 | F31: 신고 요건 안내 미흡 | G31: 문의할 곳이 없어 다시 남깁니다 "안녕하세요. 안전신문고에 관심을 가져 주셔서 감사합니다. 시간 순서가 사진 사진-동영상 순으로 첨부 가능합니다. 파일의 촬영 시간 확인해 주시기 바랍니다. 보다 안정적인 앱 사용을 위해 더욱 노력하겠습니다. 감사합니다." 위와같은 답변을 받았는데 사진과 사진 사이에 동영상을 찍는 경우가 있는데 왜 설정이 그렇게 되어있는지 확인 부탁드립니다 친환경차 주차구역의 경우 단순 바닥의 주차구역 표시 촬영을 위해 동영상으로 찍기 때문에 첫 번째 사진과 두 번째 사진 사이에 촬영했습니다 지금 신고 접수를 못 하고 있는데 시간 순서가 사진 사진 - 동영상 순이어야 한다는 안내가 어디에 되어있는지 알려주시겠어요?
A32: 30 | B32: 2026-09-10 | C32: 1 | D32: 0 | E32: 고장 | F32: 사진 촬영·저장 실패, 앱 튕김·먹통·프리징 | G32: 신고를 하려해도 앱 사진이 저장이 안된다하고 앱이 튕겨나가서 신고를 할수가 없습니다
A33: 31 | B33: 2026-09-09 | C33: 1 | D33: 1 | G33: 쓰레기 앱 정부는 관리 제대로 해라 세금마깝다
A34: 32 | B34: 2026-09-09 | C34: 1 | D34: 0 | E34: 설계 | F34: 갤러리 사진 첨부 불가(앱 카메라 강제) | G34: 안전신고 갤러리에 있는 사진이 등록이 안됩니다.
A35: 33 | B35: 2026-09-09 | C35: 1 | D35: 0 | E35: 고장 | F35: 제출·다음 단계 진행 불가 | G35: 사진업로드가 안돼요
A36: 34 | B36: 2026-09-09 | C36: 1 | D36: 0 | E36: 고장 | F36: 앱 튕김·먹통·프리징, 로그인·인증·가입 실패 | G36: 로그인하려는데... 최신 소스가 아닙니다. 앱종료후 다시 실행하라는데... 다시 실행해도 안되는거 똑같다. 앱 정비 좀 해라.
A37: 35 | B37: 2026-09-09 | C37: 1 | D37: 0 | G37: 깔고 들어가면 계속 밑에 바 숫자나오고 계속 다운만받네요. 관리를 안하는듯.
A38: 36 | B38: 2026-09-08 | C38: 1 | D38: 0 | E38: 행정처리 | F38: 불수용·반려에 대한 불신, 처리 지연·결과 안내 없음 | G38: 이건 누가관리합니까? 교통법규 신호위반신고 2달이넘어가는데도 깜깜무소식이네.. 심할땐8개월만에 처리한결과는 경고장 발부뿐.... 어처구니 없는건 오토바이 신고당하면 5일만에 카톡으로 발부장오던데..
A39: 37 | B39: 2026-09-08 | C39: 1 | D39: 0 | G39: 업무처리 속도가너무 늦어요
A40: 38 | B40: 2026-09-07 | C40: 1 | D40: 1 | G40: 아니 사진을 2장 찍어야한다면서 1장만 찍을 수 있게 해놓는건 뭐죠?
...

Sheet 주제 집계
A1: 성격 | B1: 주제 | C1: 건수 | D1: 비율 | I1: 전체 리뷰 수 | J1: =COUNTA('리뷰 655건'!$A$2:$A$656) -> 655
A2: 설계 | B2: 갤러리 사진 첨부 불가(앱 카메라 강제) | C2: =COUNTIF('리뷰 655건'!$F$2:$F$656,"*"&B2&"*") -> 87 | D2: =C2/$J$1 -> 0.13282443
A3: 설계 | B3: 사진 화질 저하로 번호판 식별 불가 | C3: =COUNTIF('리뷰 655건'!$F$2:$F$656,"*"&B3&"*") -> 24 | D3: =C3/$J$1 -> 0.036641221
A4: 설계 | B4: 1분 대기·현장 체류 | C4: =COUNTIF('리뷰 655건'!$F$2:$F$656,"*"&B4&"*") -> 22 | D4: =C4/$J$1 -> 0.033587786
A5: 설계 | B5: 신고 요건 안내 미흡 | C5: =COUNTIF('리뷰 655건'!$F$2:$F$656,"*"&B5&"*") -> 13 | D5: =C5/$J$1 -> 0.019847328
A6: 설계 | B6: 작성 중 내용 유실·임시저장 없음 | C6: =COUNTIF('리뷰 655건'!$F$2:$F$656,"*"&B6&"*") -> 6 | D6: =C6/$J$1 -> 0.0091603053
A7: 설계 | B7: 촬영 시각·위치가 자동으로 안 붙음 | C7: =COUNTIF('리뷰 655건'!$F$2:$F$656,"*"&B7&"*") -> 10 | D7: =C7/$J$1 -> 0.015267176
A8: 설계 | B8: 입력·화면 이동이 번거로움 | C8: =COUNTIF('리뷰 655건'!$F$2:$F$656,"*"&B8&"*") -> 13 | D8: =C8/$J$1 -> 0.019847328
A9: 고장 | B9: 사진 촬영·저장 실패 | C9: =COUNTIF('리뷰 655건'!$F$2:$F$656,"*"&B9&"*") -> 70 | D9: =C9/$J$1 -> 0.10687023
A10: 고장 | B10: 앱 튕김·먹통·프리징 | C10: =COUNTIF('리뷰 655건'!$F$2:$F$656,"*"&B10&"*") -> 44 | D10: =C10/$J$1 -> 0.067175573
A11: 고장 | B11: 제출·다음 단계 진행 불가 | C11: =COUNTIF('리뷰 655건'!$F$2:$F$656,"*"&B11&"*") -> 47 | D11: =C11/$J$1 -> 0.071755725
A12: 고장 | B12: 느림·로딩·버퍼링 | C12: =COUNTIF('리뷰 655건'!$F$2:$F$656,"*"&B12&"*") -> 53 | D12: =C12/$J$1 -> 0.080916031
A13: 고장 | B13: 로그인·인증·가입 실패 | C13: =COUNTIF('리뷰 655건'!$F$2:$F$656,"*"&B13&"*") -> 27 | D13: =C13/$J$1 -> 0.041221374
... A15: 행정처리 | B15: 처리 지연·결과 안내 없음 | C15: =COUNTIF('리뷰 655건'!$F$2:$F$656,"*"&B15&"*") -> 21 | D15: =C15/$J$1 -> 0.032061069
B17: 성격별 — 이 성격의 불만을 담은 리뷰 수 (한 리뷰가 여러 성격에 걸칠 수 있음)
A18: 설계 | B18: 설계 — 고장이 다 고쳐져도 남는다 (제안 대상) | C18: =COUNTIF('리뷰 655건'!$E$2:$E$656,"*"&A18&"*") -> 146 | D18: =C18/$J$1 -> 0.22290076
A19: 고장 | B19: 고장 — 고치면 사라진다 (제안 대상 아님) | C19: =COUNTIF('리뷰 655건'!$E$2:$E$656,"*"&A19&"*") -> 218 | D19: =C19/$J$1 -> 0.33282443
A20: 행정처리 | B20: 행정 처리 — 앱 화면 밖 | C20: =COUNTIF('리뷰 655건'!$E$2:$E$656,"*"&A20&"*") -> 47 | D20: =C20/$J$1 -> 0.071755725

Sheet 월별 추이
A1: 월 | B1: 전체 | C1: 설계 | D1: 고장 | E1: 행정처리 | F1: 갤러리 차단 | G1: 설계 비율
A2: 2026-01 | B2: =COUNTIF('리뷰 655건'!$B$2:$B$656,A2&"*") -> 59 | C2: =COUNTIFS('리뷰 655건'!$B$2:$B$656,A2&"*",'리뷰 655건'!$E$2:$E$656,"*설계*") -> 14 | D2: =COUNTIFS('리뷰 655건'!$B$2:$B$656,A2&"*",'리뷰 655건'!$E$2:$E$656,"*고장*") -> 17 | E2: =COUNTIFS('리뷰 655건'!$B$2:$B$656,A2&"*",'리뷰 655건'!$E$2:$E$656,"*행정처리*") -> 6 | F2: =COUNTIFS('리뷰 655건'!$B$2:$B$656,A2&"*",'리뷰 655건'!$F$2:$F$656,"*갤러리 사진 첨부 불가*") -> 11 | G2: =IFERROR(C2/B2,0) -> 0.23728814
A3: 2026-02 | B3: =COUNTIF('리뷰 655건'!$B$2:$B$656,A3&"*") -> 53 | C3: =COUNTIFS('리뷰 655건'!$B$2:$B$656,A3&"*",'리뷰 655건'!$E$2:$E$656,"*설계*") -> 6 | D3: =COUNTIFS('리뷰 655건'!$B$2:$B$656,A3&"*",'리뷰 655건'!$E$2:$E$656,"*고장*") -> 18 | E3: =COUNTIFS('리뷰 655건'!$B$2:$B$656,A3&"*",'리뷰 655건'!$E$2:$E$656,"*행정처리*") -> 2 | F3: =COUNTIFS('리뷰 655건'!$B$2:$B$656,A3&"*",'리뷰 655건'!$F$2:$F$656,"*갤러리 사진 첨부 불가*") -> 4 | G3: =IFERROR(C3/B3,0) -> 0.11320755
A4: 2026-03 | B4: =COUNTIF('리뷰 655건'!$B$2:$B$656,A4&"*") -> 74 | C4: =COUNTIFS('리뷰 655건'!$B$2:$B$656,A4&"*",'리뷰 655건'!$E$2:$E$656,"*설계*") -> 18 | D4: =COUNTIFS('리뷰 655건'!$B$2:$B$656,A4&"*",'리뷰 655건'!$E$2:$E$656,"*고장*") -> 17 | E4: =COUNTIFS('리뷰 655건'!$B$2:$B$656,A4&"*",'리뷰 655건'!$E$2:$E$656,"*행정처리*") -> 5 | F4: =COUNTIFS('리뷰 655건'!$B$2:$B$656,A4&"*",'리뷰 655건'!$F$2:$F$656,"*갤러리 사진 첨부 불가*") -> 12 | G4: =IFERROR(C4/B4,0) -> 0.24324324
A5: 2026-04 | B5: =COUNTIF('리뷰 655건'!$B$2:$B$656,A5&"*") -> 99 | C5: =COUNTIFS('리뷰 655건'!$B$2:$B$656,A5&"*",'리뷰 655건'!$E$2:$E$656,"*설계*") -> 21 | D5: =COUNTIFS('리뷰 655건'!$B$2:$B$656,A5&"*",'리뷰 655건'!$E$2:$E$656,"*고장*") -> 32 | E5: =COUNTIFS('리뷰 655건'!$B$2:$B$656,A5&"*",'리뷰 655건'!$E$2:$E$656,"*행정처리*") -> 5 | F5: =COUNTIFS('리뷰 655건'!$B$2:$B$656,A5&"*",'리뷰 655건'!$F$2:$F$656,"*갤러리 사진 첨부 불가*") -> 13 | G5: =IFERROR(C5/B5,0) -> 0.21212121
A6: 2026-05 | B6: =COUNTIF('리뷰 655건'!$B$2:$B$656,A6&"*") -> 89 | C6: =COUNTIFS('리뷰 655건'!$B$2:$B$656,A6&"*",'리뷰 655건'!$E$2:$E$656,"*설계*") -> 13 | D6: =COUNTIFS('리뷰 655건'!$B$2:$B$656,A6&"*",'리뷰 655건'!$E$2:$E$656,"*고장*") -> 30 | E6: =COUNTIFS('리뷰 655건'!$B$2:$B$656,A6&"*",'리뷰 655건'!$E$2:$E$656,"*행정처리*") -> 3 | F6: =COUNTIFS('리뷰 655건'!$B$2:$B$656,A6&"*",'리뷰 655건'!$F$2:$F$656,"*갤러리 사진 첨부 불가*") -> 9 | G6: =IFERROR(C6/B6,0) -> 0.14606742
A7: 2026-06 | B7: =COUNTIF('리뷰 655건'!$B$2:$B$656,A7&"*") -> 75 | C7: =COUNTIFS('리뷰 655건'!$B$2:$B$656,A7&"*",'리뷰 655건'!$E$2:$E$656,"*설계*") -> 14 | D7: =COUNTIFS('리뷰 655건'!$B$2:$B$656,A7&"*",'리뷰 655건'!$E$2:$E$656,"*고장*") -> 19 | E7: =COUNTIFS('리뷰 655건'!$B$2:$B$656,A7&"*",'리뷰 655건'!$E$2:$E$656,"*행정처리*") -> 9 | F7: =COUNTIFS('리뷰 655건'!$B$2:$B$656,A7&"*",'리뷰 655건'!$F$2:$F$656,"*갤러리 사진 첨부 불가*") -> 7 | G7: =IFERROR(C7/B7,0) -> 0.18666667
A8: 2026-07 | B8: =COUNTIF('리뷰 655건'!$B$2:$B$656,A8&"*") -> 67 | C8: =COUNTIFS('리뷰 655건'!$B$2:$B$656,A8&"*",'리뷰 655건'!$E$2:$E$656,"*설계*") -> 27 | D8: =COUNTIFS('리뷰 655건'!$B$2:$B$656,A8&"*",'리뷰 655건'!$E$2:$E$656,"*고장*") -> 22 | E8: =COUNTIFS('리뷰 655건'!$B$2:$B$656,A8&"*",'리뷰 655건'!$E$2:$E$656,"*행정처리*") -> 6 | F8: =COUNTIFS('리뷰 655건'!$B$2:$B$656,A8&"*",'리뷰 655건'!$F$2:$F$656,"*갤러리 사진 첨부 불가*") -> 11 | G8: =IFERROR(C8/B8,0) -> 0.40298507
A9: 2026-08 | B9: =COUNTIF('리뷰 655건'!$B$2:$B$656,A9&"*") -> 85 | C9: =COUNTIFS('리뷰 655건'!$B$2:$B$656,A9&"*",'리뷰 655건'!$E$2:$E$656,"*설계*") -> 22 | D9: =COUNTIFS('리뷰 655건'!$B$2:$B$656,A9&"*",'리뷰 655건'!$E$2:$E$656,"*고장*") -> 36 | E9: =COUNTIFS('리뷰 655건'!$B$2:$B$656,A9&"*",'리뷰 655건'!$E$2:$E$656,"*행정처리*") -> 7 | F9: =COUNTIFS('리뷰 655건'!$B$2:$B$656,A9&"*",'리뷰 655건'!$F$2:$F$656,"*갤러리 사진 첨부 불가*") -> 15 | G9: =IFERROR(C9/B9,0) -> 0.25882353
A10: 2026-09 | B10: =COUNTIF('리뷰 655건'!$B$2:$B$656,A10&"*") -> 54 | C10: =COUNTIFS('리뷰 655건'!$B$2:$B$656,A10&"*",'리뷰 655건'!$E$2:$E$656,"*설계*") -> 11 | D10: =COUNTIFS('리뷰 655건'!$B$2:$B$656,A10&"*",'리뷰 655건'!$E$2:$E$656,"*고장*") -> 27 | E10: =COUNTIFS('리뷰 655건'!$B$2:$B$656,A10&"*",'리뷰 655건'!$E$2:$E$656,"*행정처리*") -> 4 | F10: =COUNTIFS('리뷰 655건'!$B$2:$B$656,A10&"*",'리뷰 655건'!$F$2:$F$656,"*갤러리 사진 첨부 불가*") -> 5 | G10: =IFERROR(C10/B10,0) -> 0.2037037

Sheet 별점 분포
A1: 별점 | B1: 건수 | C1: 비율
A2: 5 | B2: =COUNTIF('리뷰 655건'!$C$2:$C$656,A2) -> 15 | C2: =B2/'주제 집계'!$J$1 -> 0.022900763
A3: 4 | B3: =COUNTIF('리뷰 655건'!$C$2:$C$656,A3) -> 9 | C3: =B3/'주제 집계'!$J$1 -> 0.013740458
A4: 3 | B4: =COUNTIF('리뷰 655건'!$C$2:$C$656,A4) -> 22 | C4: =B4/'주제 집계'!$J$1 -> 0.033587786
A5: 2 | B5: =COUNTIF('리뷰 655건'!$C$2:$C$656,A5) -> 28 | C5: =B5/'주제 집계'!$J$1 -> 0.042748092
A6: 1 | B6: =COUNTIF('리뷰 655건'!$C$2:$C$656,A6) -> 581 | C6: =B6/'주제 집계'!$J$1 -> 0.8870229

Sheet 수집·분류 방법
A1: 항목 | B1: 내용
A2: 무엇인가 | B2: 구글플레이 '안전신문고' 앱 리뷰 중 2026년에 작성된 655건과 그 분류 결과.
A3: 대상 기간 | B3: 2026-01-01 ~ 2026-09-17 (2026-09-18 수집). 2025년 이전 리뷰는 제외했다.
A4: 출처 | B4: https://play.google.com/store/apps/details?id=kr.go.safepeople
A5: 수집 방법 | B5: 스토어 리뷰 화면을 브라우저로 열어 '최신순'으로 정렬하고, 화면에 표시된 리뷰를 그대로 옮겼다. 비공개 API나 우회 수집을 쓰지 않았다.
A6: 작성자 이름 | B6: 저장하지 않았다. 개인정보이고 분석에 필요 없다.
A7: 욕설 | B7: 욕설만 있는 리뷰 몇 건은 본문을 '(욕설 리뷰)'로 대체했다.
A8: 분류 방식 | B8: 규칙(키워드) 기반이라 다시 돌려도 같은 숫자가 나온다. 한 리뷰가 여러 주제에 걸칠 수 있어 주제별 건수의 합은 655를 넘는다.
A9: 성격 구분 | B9: 설계 = 고장이 다 고쳐져도 남는 것(제안 대상) · 고장 = 고치면 사라지는 것 · 행정처리 = 접수 이후, 앱 화면 밖의 문제
A10: 분류 안 된 리뷰 | B10: 키워드가 하나도 안 걸린 리뷰는 성격·주제 칸이 비어 있다. 대부분 욕설이나 한 줄 불평이라 억지로 끼워 맞추지 않았다.
A11: 다시 돌리려면 | B11: data/classify.py 와 data/play-reviews-2026.tsv 를 쓴다.
A12: 한계 | B12: ① 구글플레이만이다. App Store 는 별도로 봐야 한다. ② 리뷰는 앱 전체에 대한 것이라 주정차와 무관한 불만도 섞여 있다. ③ 리뷰는 화난 사람이 쓴다 — 전체 이용자의 대표 표본이 아니다.
